<sdf version='1.10'>
  <world name='car_world'>
    <physics name='1ms' type='ignored'>
      <max_step_size>0.001</max_step_size>
      <real_time_factor>1</real_time_factor>
      <real_time_update_rate>1000</real_time_update_rate>
    </physics>
    <plugin name='gz::sim::systems::Physics' filename='gz-sim-physics-system'/>
    <plugin name='gz::sim::systems::UserCommands' filename='gz-sim-user-commands-system'/>
    <plugin name='gz::sim::systems::SceneBroadcaster' filename='gz-sim-scene-broadcaster-system'/>
    <gravity>0 0 -9.8000000000000007</gravity>
    <magnetic_field>5.5644999999999998e-06 2.2875799999999999e-05 -4.2388400000000002e-05</magnetic_field>
    <atmosphere type='adiabatic'/>
    <scene>
      <ambient>0.400000006 0.400000006 0.400000006 1</ambient>
      <background>0.699999988 0.699999988 0.699999988 1</background>
      <shadows>true</shadows>
    </scene>
    <model name='ground_plane'>
      <static>true</static>
      <link name='link'>
        <collision name='collision'>
          <geometry>
            <plane>
              <normal>0 0 1</normal>
              <size>1 1</size>
            </plane>
          </geometry>
          <surface>
            <friction>
              <ode/>
            </friction>
            <bounce/>
            <contact/>
          </surface>
        </collision>
        <visual name='visual'>
          <geometry>
            <plane>
              <normal>0 0 1</normal>
              <size>100 100</size>
            </plane>
          </geometry>
          <material>
            <ambient>0.800000012 0.800000012 0.800000012 1</ambient>
            <diffuse>0.800000012 0.800000012 0.800000012 1</diffuse>
            <specular>0.800000012 0.800000012 0.800000012 1</specular>
          </material>
        </visual>
        <pose>0 0 0 0 0 0</pose>
        <inertial>
          <pose>0 0 0 0 0 0</pose>
          <mass>1</mass>
          <inertia>
            <ixx>1</ixx>
            <ixy>0</ixy>
            <ixz>0</ixz>
            <iyy>1</iyy>
            <iyz>0</iyz>
            <izz>1</izz>
          </inertia>
        </inertial>
        <enable_wind>false</enable_wind>
      </link>
      <pose>0 0 0 0 0 0</pose>
      <self_collide>false</self_collide>
    </model>
    <include>
      <uri>file:///home/jeff/harm_ws/src/harm/models/room_wall_2x5m</uri>
      <name>A1</name>
      <pose>-2 2.5130422115325928 1 0 0 0</pose>
    </include>
    <include>
      <uri>file:///home/jeff/harm_ws/src/harm/models/room_wall_2x5m</uri>
      <name>A2</name>
      <pose>2 2.4840750694274902 1 0 0 0</pose>
    </include>
    <model name='vehicle_blue' canonical_link='chassis'>
      <pose>0 0 0 0 0 0</pose>
      <link name='chassis'>
        <pose>0.5 0 0.40000000000000002 0 0 0</pose>
        <inertial>
          <mass>1.14395</mass>
          <inertia>
            <ixx>0.095328999999999997</ixx>
            <ixy>0</ixy>
            <ixz>0</ixz>
            <iyy>0.38131700000000002</iyy>
            <iyz>0</iyz>
            <izz>0.47664600000000001</izz>
          </inertia>
          <pose>0 0 0 0 0 0</pose>
        </inertial>
        <visual name='visual'>
          <geometry>
            <box>
              <size>2 1 0.5</size>
            </box>
          </geometry>
          <material>
            <ambient>0 0 1 1</ambient>
            <diffuse>0 0 1 1</diffuse>
            <specular>0 0 1 1</specular>
          </material>
        </visual>
        <collision name='collision'>
          <geometry>
            <box>
              <size>2 1 0.5</size>
            </box>
          </geometry>
          <surface>
            <friction>
              <ode/>
            </friction>
            <bounce/>
            <contact/>
          </surface>
        </collision>
        <enable_wind>false</enable_wind>
      </link>
      <link name='left_wheel'>
        <pose>0 0.59999999999999998 0.40000000000000002 -1.5706999999999995 0 0</pose>
        <inertial>
          <mass>1</mass>
          <inertia>
            <ixx>0.043333000000000003</ixx>
            <ixy>0</ixy>
            <ixz>0</ixz>
            <iyy>0.043333000000000003</iyy>
            <iyz>0</iyz>
            <izz>0.080000000000000002</izz>
          </inertia>
          <pose>0 0 0 0 0 0</pose>
        </inertial>
        <visual name='visual'>
          <geometry>
            <cylinder>
              <radius>0.40000000000000002</radius>
              <length>0.20000000000000001</length>
            </cylinder>
          </geometry>
          <material>
            <ambient>1 0 0 1</ambient>
            <diffuse>1 0 0 1</diffuse>
            <specular>1 0 0 1</specular>
          </material>
        </visual>
        <collision name='collision'>
          <geometry>
            <cylinder>
              <radius>0.40000000000000002</radius>
              <length>0.20000000000000001</length>
            </cylinder>
          </geometry>
          <surface>
            <friction>
              <ode/>
            </friction>
            <bounce/>
            <contact/>
          </surface>
        </collision>
        <enable_wind>false</enable_wind>
      </link>
      <link name='right_wheel'>
        <pose>0 -0.59999999999999998 0.40000000000000002 -1.5706999999999995 0 0</pose>
        <inertial>
          <mass>1</mass>
          <inertia>
            <ixx>0.043333000000000003</ixx>
            <ixy>0</ixy>
            <ixz>0</ixz>
            <iyy>0.043333000000000003</iyy>
            <iyz>0</iyz>
            <izz>0.080000000000000002</izz>
          </inertia>
          <pose>0 0 0 0 0 0</pose>
        </inertial>
        <visual name='visual'>
          <geometry>
            <cylinder>
              <radius>0.40000000000000002</radius>
              <length>0.20000000000000001</length>
            </cylinder>
          </geometry>
          <material>
            <ambient>1 0 0 1</ambient>
            <diffuse>1 0 0 1</diffuse>
            <specular>1 0 0 1</specular>
          </material>
        </visual>
        <collision name='collision'>
          <geometry>
            <cylinder>
              <radius>0.40000000000000002</radius>
              <length>0.20000000000000001</length>
            </cylinder>
          </geometry>
          <surface>
            <friction>
              <ode/>
            </friction>
            <bounce/>
            <contact/>
          </surface>
        </collision>
        <enable_wind>false</enable_wind>
      </link>
      <frame name='caster_frame' attached_to='chassis'>
        <pose>0.80000000000000004 0 -0.20000000000000001 0 0 0</pose>
      </frame>
      <link name='caster'>
        <pose>1.3 0 0.20000000000000001 0 0 0</pose>
        <inertial>
          <mass>1</mass>
          <inertia>
            <ixx>0.016</ixx>
            <ixy>0</ixy>
            <ixz>0</ixz>
            <iyy>0.016</iyy>
            <iyz>0</iyz>
            <izz>0.016</izz>
          </inertia>
          <pose>0 0 0 0 0 0</pose>
        </inertial>
        <visual name='visual'>
          <geometry>
            <sphere>
              <radius>0.20000000000000001</radius>
            </sphere>
          </geometry>
          <material>
            <ambient>0 1 0 1</ambient>
            <diffuse>0 1 0 1</diffuse>
            <specular>0 1 0 1</specular>
          </material>
        </visual>
        <collision name='collision'>
          <geometry>
            <sphere>
              <radius>0.20000000000000001</radius>
            </sphere>
          </geometry>
          <surface>
            <friction>
              <ode/>
            </friction>
            <bounce/>
            <contact/>
          </surface>
        </collision>
        <enable_wind>false</enable_wind>
      </link>
      <joint name='left_wheel_joint' type='revolute'>
        <pose>0 0 0 0 0 0</pose>
        <parent>chassis</parent>
        <child>left_wheel</child>
        <axis>
          <xyz>0 9.6326794747692026e-05 0.99999999536057438</xyz>
          <limit>
            <lower>-1.7976900000000001e+308</lower>
            <upper>1.7976900000000001e+308</upper>
            <effort>inf</effort>
            <velocity>inf</velocity>
            <stiffness>100000000</stiffness>
            <dissipation>1</dissipation>
          </limit>
          <dynamics>
            <spring_reference>0</spring_reference>
            <spring_stiffness>0</spring_stiffness>
            <damping>0</damping>
            <friction>0</friction>
          </dynamics>
        </axis>
      </joint>
      <joint name='right_wheel_joint' type='revolute'>
        <pose>0 1.6653345369377348e-16 0 0 0 0</pose>
        <parent>chassis</parent>
        <child>right_wheel</child>
        <axis>
          <xyz>0 9.6326794747692026e-05 0.99999999536057438</xyz>
          <limit>
            <lower>-1.7976900000000001e+308</lower>
            <upper>1.7976900000000001e+308</upper>
            <effort>inf</effort>
            <velocity>inf</velocity>
            <stiffness>100000000</stiffness>
            <dissipation>1</dissipation>
          </limit>
          <dynamics>
            <spring_reference>0</spring_reference>
            <spring_stiffness>0</spring_stiffness>
            <damping>0</damping>
            <friction>0</friction>
          </dynamics>
        </axis>
      </joint>
      <joint name='caster_wheel' type='ball'>
        <parent>chassis</parent>
        <child>caster</child>
        <pose>0 0 0 0 0 0</pose>
      </joint>
      <plugin name='gz::sim::systems::DiffDrive' filename='gz-sim-diff-drive-system'>
        <left_joint>left_wheel_joint</left_joint>
        <right_joint>right_wheel_joint</right_joint>
        <wheel_separation>1.2</wheel_separation>
        <wheel_radius>0.4</wheel_radius>
        <odom_publish_frequency>1</odom_publish_frequency>
        <topic>cmd_vel</topic>
      </plugin>
      <plugin name='gz::sim::systems::TriggeredPublisher' filename='gz-sim-triggered-publisher-system'>
        <input type='gz.msgs.Int32' topic='/keyboard/keypress'>
          <match field='data'>16777235</match>
        </input>
        <output type='gz.msgs.Twist' topic='/cmd_vel'>linear: {x: 0.5}, angular: {z: 0.0}</output>
      </plugin>
      <plugin name='gz::sim::systems::TriggeredPublisher' filename='gz-sim-triggered-publisher-system'>
        <input type='gz.msgs.Int32' topic='/keyboard/keypress'>
          <match field='data'>16777237</match>
        </input>
        <output type='gz.msgs.Twist' topic='/cmd_vel'>linear: {x: -0.5}, angular: {z: 0.0}</output>
      </plugin>
      <plugin name='gz::sim::systems::TriggeredPublisher' filename='gz-sim-triggered-publisher-system'>
        <input type='gz.msgs.Int32' topic='/keyboard/keypress'>
          <match field='data'>16777234</match>
        </input>
        <output type='gz.msgs.Twist' topic='/cmd_vel'>linear: { x: 0.0 }, angular: { z: 0.5 }</output>
      </plugin>
      <plugin name='gz::sim::systems::TriggeredPublisher' filename='gz-sim-triggered-publisher-system'>
        <input type='gz.msgs.Int32' topic='/keyboard/keypress'>
          <match field='data'>16777236</match>
        </input>
        <output type='gz.msgs.Twist' topic='/cmd_vel'>linear: { x: 0.0 }, angular: { z: -0.5 }</output>
      </plugin>
      <static>false</static>
      <self_collide>false</self_collide>
    </model>
    <include>
      <uri>file:///home/jeff/harm_ws/src/harm/models/room_wall_2x5m</uri>
      <name>A1_1</name>
      <pose>2 -2 1 0 0 0</pose>
    </include>
    <include>
      <uri>file:///home/jeff/harm_ws/src/harm/models/room_wall_2x5m</uri>
      <name>A1_2</name>
      <pose>2 -7 1 0 0 0</pose>
    </include>
    <include>
      <uri>file:///home/jeff/harm_ws/src/harm/models/room_wall_2x5m</uri>
      <name>A1_3</name>
      <pose>2 -9.5 1 0 0 0</pose>
    </include>
    <include>
      <uri>file://../models/room_wall_2x5m</uri>
      <name>A1_4</name>
      <pose>-1 -7 1 0 0 90</pose>
    </include>
    <light name='sun' type='directional'>
      <pose>0 0 10 0 0 0</pose>
      <cast_shadows>true</cast_shadows>
      <intensity>1</intensity>
      <direction>-0.5 0.10000000000000001 -0.90000000000000002</direction>
      <diffuse>0.800000012 0.800000012 0.800000012 1</diffuse>
      <specular>0.200000003 0.200000003 0.200000003 1</specular>
      <attenuation>
        <range>1000</range>
        <linear>0.01</linear>
        <constant>0.90000000000000002</constant>
        <quadratic>0.001</quadratic>
      </attenuation>
      <spot>
        <inner_angle>0</inner_angle>
        <outer_angle>0</outer_angle>
        <falloff>0</falloff>
      </spot>
    </light>
  </world>
</sdf>
