<sdf version='1.9'>
      <world name="car_world">
        <physics name="1ms" type="ignored">
            <max_step_size>0.001</max_step_size>
            <real_time_factor>1.0</real_time_factor>
        </physics>
        <plugin
            filename="libignition-gazebo-physics-system.so"
            name="ignition::gazebo::systems::Physics">
        </plugin>
        <plugin
            filename="libignition-gazebo-user-commands-system.so"
            name="ignition::gazebo::systems::UserCommands">
        </plugin>
        <plugin
            filename="libignition-gazebo-scene-broadcaster-system.so"
            name="ignition::gazebo::systems::SceneBroadcaster">
        </plugin>

        <light type="directional" name="sun">
            <cast_shadows>true</cast_shadows>
            <pose>0 0 10 0 0 0</pose>
            <diffuse>0.8 0.8 0.8 1</diffuse>
            <specular>0.2 0.2 0.2 1</specular>
            <attenuation>
                <range>1000</range>
                <constant>0.9</constant>
                <linear>0.01</linear>
                <quadratic>0.001</quadratic>
            </attenuation>
            <direction>-0.5 0.1 -0.9</direction>
        </light>

        <model name="ground_plane">
            <static>true</static>
            <link name="link">
                <collision name="collision">
                    <geometry>
                        <plane>
                            <normal>0 0 1</normal>
                        </plane>
                    </geometry>
                </collision>
                <visual name="visual">
                    <geometry>
                        <plane>
                            <normal>0 0 1</normal>
                            <size>100 100</size>
                        </plane>
                    </geometry>
                    <material>
                        <ambient>0.8 0.8 0.8 1</ambient>
                        <diffuse>0.8 0.8 0.8 1</diffuse>
                        <specular>0.8 0.8 0.8 1</specular>
                    </material>
                </visual>
            </link>
        </model>
  <model name='Seguidor_linea_robot'>
    <link name='base_link'>
      <inertial>
        <pose>0.010085 -7.876299999999999e-06 -0.0066048 0 0 0</pose>
        <mass>0.12859000000000001</mass>
        <inertia>
          <ixx>5.2145999999999998e-05</ixx>
          <ixy>-1.2223e-19</ixy>
          <ixz>2.9402999999999999e-20</ixz>
          <iyy>0.00017956999999999999</iyy>
          <iyz>1.8099e-14</iyz>
          <izz>0.00022798999999999999</izz>
        </inertia>
      </inertial>
      <collision name='base_link_collision'>
        <pose>0 0 0 0 0 0</pose>
        <geometry>
          <mesh>
            <scale>1 1 1</scale>
            <uri>model://modelo_robot/meshes/base_link.STL</uri>
          </mesh>
        </geometry>
      </collision>
      <visual name='base_link_visual'>
        <pose>0 0 0 0 0 0</pose>
        <geometry>
          <mesh>
            <scale>1 1 1</scale>
            <uri>model://modelo_robot/meshes/base_link.STL</uri>
          </mesh>
        </geometry>
        <material>
          <diffuse>1 1 1 0.3</diffuse>
          <ambient>1 1 1 0.3</ambient>
        </material>
      </visual>
    </link>
    <joint name='Base_castor_joint' type='revolute'>
      <pose relative_to='base_link'>0.07258100000000001 0 -0.0025 -3.1408 0 0</pose>
      <parent>base_link</parent>
      <child>Base_castor_link</child>
      <axis>
        <xyz>0 0 1</xyz>
        <limit>
          <effort>100</effort>
          <velocity>100</velocity>
          <lower>-10000000000000000</lower>
          <upper>10000000000000000</upper>
        </limit>
        <dynamics>
          <damping>0.10000000000000001</damping>
          <friction>0.10000000000000001</friction>
          <spring_reference>0</spring_reference>
          <spring_stiffness>0</spring_stiffness>
        </dynamics>
      </axis>
    </joint>
    <link name='Base_castor_link'>
      <pose relative_to='Base_castor_joint'>0 0 0 0 0 0</pose>
      <inertial>
        <pose>0 0 0 0 0 0</pose>
        <mass>0.002</mass>
        <inertia>
          <ixx>0.0001</ixx>
          <ixy>0</ixy>
          <ixz>0</ixz>
          <iyy>0.0001</iyy>
          <iyz>0</iyz>
          <izz>0.0001</izz>
        </inertia>
      </inertial>
      <collision name='Base_castor_link_collision'>
        <pose>0 0 0 0 0 0</pose>
        <geometry>
          <mesh>
            <scale>1 1 1</scale>
            <uri>model://modelo_robot/meshes/Base_castor_link.STL</uri>
          </mesh>
        </geometry>
      </collision>
      <visual name='Base_castor_link_visual'>
        <pose>0 0 0 0 0 0</pose>
        <geometry>
          <mesh>
            <scale>1 1 1</scale>
            <uri>model://modelo_robot/meshes/Base_castor_link.STL</uri>
          </mesh>
        </geometry>
        <material>
          <diffuse>1 1 1 1</diffuse>
          <ambient>1 1 1 1</ambient>
        </material>
      </visual>
    </link>
    <joint name='Rueda_castor_joint' type='revolute'>
      <pose relative_to='Base_castor_link'>0.015014 -0.00012272 0.02296 0 -1.569999999999988 1.570800000000018</pose>
      <parent>Base_castor_link</parent>
      <child>Rueda_castor_link</child>
      <axis>
        <xyz>0 0 1</xyz>
        <limit>
          <effort>100</effort>
          <velocity>100</velocity>
          <lower>-10000000000000000</lower>
          <upper>10000000000000000</upper>
        </limit>
        <dynamics>
          <damping>0.10000000000000001</damping>
          <friction>0.10000000000000001</friction>
          <spring_reference>0</spring_reference>
          <spring_stiffness>0</spring_stiffness>
        </dynamics>
      </axis>
    </joint>
    <link name='Rueda_castor_link'>
      <pose relative_to='Rueda_castor_joint'>0 0 0 0 0 0</pose>
      <inertial>
        <pose>6.93889390390723e-18 -2.62037475051713e-11 -2.77710070911708e-09 0 0 0</pose>
        <mass>0.0082873999231907608</mass>
        <inertia>
          <ixx>6.3926680927577005e-07</ixx>
          <ixy>-7.3165723907688895e-23</ixy>
          <ixz>4.9980054406097498e-23</ixz>
          <iyy>6.3929991277458396e-07</iyy>
          <iyz>3.5083463400717699e-09</iyz>
          <izz>1.0110853324803701e-06</izz>
        </inertia>
      </inertial>
      <collision name='Rueda_castor_link_collision'>
        <pose>0 0 0 0 0 0</pose>
        <geometry>
          <mesh>
            <scale>1 1 1</scale>
            <uri>model://modelo_robot/meshes/Rueda_castor_link.STL</uri>
          </mesh>
        </geometry>
      </collision>
      <visual name='Rueda_castor_link_visual'>
        <pose>0 0 0 0 0 0</pose>
        <geometry>
          <mesh>
            <scale>1 1 1</scale>
            <uri>model://modelo_robot/meshes/Rueda_castor_link.STL</uri>
          </mesh>
        </geometry>
        <material>
          <diffuse>1 1 1 1</diffuse>
          <ambient>1 1 1 1</ambient>
        </material>
      </visual>
    </link>
    <joint name='Rueda_derecha_joint' type='revolute'>
      <pose relative_to='base_link'>-0.033259 -0.08025 -0.01375 1.5708 0.042481 3.141585307179587</pose>
      <parent>base_link</parent>
      <child>Rueda_derecha_link</child>
      <axis>
        <xyz>0 0 1</xyz>
        <limit>
          <effort>100</effort>
          <velocity>100</velocity>
          <lower>-10000000000000000</lower>
          <upper>10000000000000000</upper>
        </limit>
        <dynamics>
          <damping>0.10000000000000001</damping>
          <friction>0.10000000000000001</friction>
          <spring_reference>0</spring_reference>
          <spring_stiffness>0</spring_stiffness>
        </dynamics>
      </axis>
    </joint>
    <link name='Rueda_derecha_link'>
      <pose relative_to='Rueda_derecha_joint'>0 0 0 0 0 0</pose>
      <inertial>
        <pose>-8.9146e-10 -3.2512e-08 0.011873 0 0 0</pose>
        <mass>0.021403999999999999</mass>
        <inertia>
          <ixx>8.6283e-06</ixx>
          <ixy>6.4380999999999997e-11</ixy>
          <ixz>-1.062e-13</ixz>
          <iyy>8.6269000000000004e-06</iyy>
          <iyz>9.8998999999999999e-12</iyz>
          <izz>1.4515000000000001e-05</izz>
        </inertia>
      </inertial>
      <collision name='Rueda_derecha_link_collision'>
        <pose>0 0 0 0 0 0</pose>
        <geometry>
          <mesh>
            <scale>1 1 1</scale>
            <uri>model://modelo_robot/meshes/Rueda_derecha_link.STL</uri>
          </mesh>
        </geometry>
      </collision>
      <visual name='Rueda_derecha_link_visual'>
        <pose>0 0 0 0 0 0</pose>
        <geometry>
          <mesh>
            <scale>1 1 1</scale>
            <uri>model://modelo_robot/meshes/Rueda_derecha_link.STL</uri>
          </mesh>
        </geometry>
        <material>
          <diffuse>0.9902 1 1 1</diffuse>
          <ambient>0.9902 1 1 1</ambient>
        </material>
      </visual>
    </link>
    <joint name='Rueda_izquierda_joint' type='revolute'>
      <pose relative_to='base_link'>-0.033259 0.08025 -0.01375 -1.5708 0.04248099999999999 3.472579850962543e-18</pose>
      <parent>base_link</parent>
      <child>Rueda_izquierda_link</child>
      <axis>
        <xyz>0 0 1</xyz>
        <limit>
          <effort>100</effort>
          <velocity>100</velocity>
          <lower>-10000000000000000</lower>
          <upper>10000000000000000</upper>
        </limit>
        <dynamics>
          <damping>0.10000000000000001</damping>
          <friction>0.10000000000000001</friction>
          <spring_reference>0</spring_reference>
          <spring_stiffness>0</spring_stiffness>
        </dynamics>
      </axis>
    </joint>
    <link name='Rueda_izquierda_link'>
      <pose relative_to='Rueda_izquierda_joint'>0 0 0 0 0 0</pose>
      <inertial>
        <pose>8.9146e-10 -3.2512e-08 -0.011873 0 0 0</pose>
        <mass>0.021403999999999999</mass>
        <inertia>
          <ixx>8.6283e-06</ixx>
          <ixy>-6.4380999999999997e-11</ixy>
          <ixz>-1.062e-13</ixz>
          <iyy>8.6269000000000004e-06</iyy>
          <iyz>-9.8998999999999999e-12</iyz>
          <izz>1.4515000000000001e-05</izz>
        </inertia>
      </inertial>
      <collision name='Rueda_izquierda_link_collision'>
        <pose>0 0 0 0 0 0</pose>
        <geometry>
          <mesh>
            <scale>1 1 1</scale>
            <uri>model://modelo_robot/meshes/Rueda_izquierda_link.STL</uri>
          </mesh>
        </geometry>
      </collision>
      <visual name='Rueda_izquierda_link_visual'>
        <pose>0 0 0 0 0 0</pose>
        <geometry>
          <mesh>
            <scale>1 1 1</scale>
            <uri>model://modelo_robot/meshes/Rueda_izquierda_link.STL</uri>
          </mesh>
        </geometry>
        <material>
          <diffuse>0.9902 1 1 1</diffuse>
          <ambient>0.9902 1 1 1</ambient>
        </material>
      </visual>
    </link>
  </model>
  </world>
</sdf>
