<?xml version="1.0"?>
<sdf version="1.9">
  <world name="car_world">
    <physics name="1ms" type="ignored">
      <max_step_size>0.001</max_step_size>
      <real_time_factor>1.0</real_time_factor>
    </physics>
    <plugin
      filename="libignition-gazebo-physics-system.so"
      name="ignition::gazebo::systems::Physics">
    </plugin>
    <plugin
      filename="libignition-gazebo-user-commands-system.so"
      name="ignition::gazebo::systems::UserCommands">
    </plugin>
    <plugin
      filename="libignition-gazebo-scene-broadcaster-system.so"
      name="ignition::gazebo::systems::SceneBroadcaster">
    </plugin>
    <plugin
      filename="libignition-gazebo-sensors-system.so"
      name="ignition::gazebo::systems::Sensors">
      <render_engine>ogre2</render_engine>
    </plugin>

    <light type="directional" name="sun">
      <cast_shadows>true</cast_shadows>
      <pose>0 0 10 0 0 0</pose>
      <diffuse>0.8 0.8 0.8 1</diffuse>
      <specular>0.2 0.2 0.2 1</specular>
      <attenuation>
        <range>1000</range>
        <constant>0.9</constant>
        <linear>0.01</linear>
        <quadratic>0.001</quadratic>
      </attenuation>
      <direction>-0.5 0.1 -0.9</direction>
    </light>

    <model name="ground_plane">
      <static>true</static>
      <link name="link">
        <collision name="collision">
          <geometry>
            <plane>
              <normal>0 0 1</normal>
            </plane>
          </geometry>
        </collision>
        <visual name="visual">
          <geometry>
            <plane>
              <normal>0 0 1</normal>
              <size>100 100</size>
            </plane>
          </geometry>
          <material>
            <ambient>0.8 0.8 0.8 1</ambient>
            <diffuse>0.8 0.8 0.8 1</diffuse>
            <specular>0.8 0.8 0.8 1</specular>
          </material>
        </visual>
      </link>
    </model>

    <model name='vehicle_blue' canonical_link='chassis_link'>
      <pose relative_to='world'>0 0 0 0 0 0</pose>
      <frame name="lidar_frame" attached_to='chassis_link'>
        <pose>-.07 0 0 0 0 -11</pose>
      </frame>
      <link name='chassis_link'>
        <pose relative_to='__model__'>0 0 .05 0 0 0</pose>
        <inertial>
          <mass>1.15</mass>
          <inertia>
            <inertia>
              <ixx>5.2146E-05</ixx>
              <ixy>-1.2223E-19</ixy>
              <ixz>2.9403E-20</ixz>
              <iyy>0.00017957</iyy>
              <iyz>1.8099E-14</iyz>
              <izz>0.00022799</izz>
            </inertia>
          </inertia>
        </inertial>
        <visual name='visual'>
          <geometry>
            <mesh>
              <uri>model://meshes/chassis_link.stl</uri>
            </mesh>
          </geometry>
          <material>
            <ambient>0.0 0.0 1.0 1</ambient>
            <diffuse>0.0 0.0 1.0 1</diffuse>
            <specular>0.0 0.0 1.0 1</specular>
          </material>
        </visual>
        <collision name='collision'>
          <geometry>
            <mesh>
              <uri>model://meshes/chassis_link.stl</uri>
            </mesh>
          </geometry>
        </collision>
        <sensor name='gpu_lidar' type='gpu_lidar'>
          <pose relative_to='lidar_frame'>0 0 0 0 0 0</pose>
          <topic>lidar</topic>
          <update_rate>10</update_rate>
          <ray>
            <scan>
              <horizontal>
                <samples>640</samples>
                <resolution>1</resolution>
                <min_angle>-1.396263</min_angle>
                <max_angle>1.396263</max_angle>
              </horizontal>
              <vertical>
                <samples>1</samples>
                <resolution>0.01</resolution>
                <min_angle>0</min_angle>
                <max_angle>0</max_angle>
              </vertical>
            </scan>
            <range>
              <min>0.08</min>
              <max>10.0</max>
              <resolution>0.01</resolution>
            </range>
          </ray>
          <always_on>1</always_on>
          <visualize>true</visualize>
        </sensor>
      </link>

      <link name="lidar_link">
        <pose relative_to='lidar_frame'>0 0 0 0 0 0</pose>
        <collision name="collision">
          <geometry>
            <mesh>
              <uri>model://meshes/LD19.stl</uri>
              <scale>.001 .001 .001</scale>
            </mesh>
          </geometry>
        </collision>
        <visual name="visual">
          <geometry>
            <mesh>
              <uri>model://meshes/LD19.stl</uri>
              <scale>.001 .001 .001</scale>
            </mesh>
          </geometry>
          <!-- add color to our link-->
          <material>
            <ambient>0.0 0.0 1.0 1</ambient>
            <diffuse>0.0 0.0 1.0 1</diffuse>
            <specular>0.0 0.0 1.0 1</specular>
          </material>
        </visual>
      </link>

      <joint name='lidar_joint' type='fixed'>
        <pose relative_to='lidar_link' />
        <parent>chassis_link</parent>
        <child>lidar_link</child>
      </joint>

      <link name='left_wheel'>
        <pose relative_to="chassis_link">-0.033259 0.08025 -0.01375 -1.5708 0.42481 0</pose>
        <inertial>
          <mass>1</mass>
          <inertia>
            <ixx>8.6283E-06</ixx>
            <ixy>-6.4381E-11</ixy>
            <ixz>-1.062E-13</ixz>
            <iyy>8.6269E-06</iyy>
            <iyz>-9.8999E-12</iyz>
            <izz>1.4515E-05</izz>
          </inertia>
        </inertial>

        <visual name='visual'>
          <geometry>
            <mesh>
              <uri>model://meshes/roda_esquerda_link.stl</uri>
            </mesh>
          </geometry>
          <material>
            <ambient>1 0 0 1</ambient>
            <diffuse>1 0 0 1</diffuse>
            <specular>1 0 0 1</specular>
          </material>
        </visual>
        <collision name='collision'>
          <geometry>
            <mesh>
              <uri>model://meshes/roda_esquerda_link.stl</uri>
            </mesh>
          </geometry>
        </collision>
      </link>
      <!-- Junta da Roda Esquerda -->
      <joint name='left_wheel_joint' type='revolute'>
        <pose relative_to='left_wheel' />
        <parent>chassis_link</parent>
        <child>left_wheel</child>
        <axis>
          <xyz expressed_in='__model__'>0 1 0</xyz>
          <limit>
            <lower>-1.79769e+308</lower>
            <upper>1.79769e+308</upper>
          </limit>
        </axis>
      </joint>

      <link name='right_wheel'>
        <pose relative_to="chassis_link">-0.033259 -0.08025 -0.01375 1.5708 0.042481 -3.1416</pose>
        <inertial>
          <mass>1</mass>
          <inertia>
            <ixx>8.6283E-06</ixx>
            <ixy>6.4381E-11</ixy>
            <ixz>-1.062E-13</ixz>
            <iyy>8.6269E-06</iyy>
            <iyz>9.8999E-12</iyz>
            <izz>1.4515E-05</izz>
          </inertia>
        </inertial>
        <visual name='visual'>
          <geometry>
            <mesh>
              <uri>model://meshes/roda_direita_link.stl</uri>
            </mesh>
          </geometry>
          <material>
            <ambient>1 0 0 1</ambient>
            <diffuse>1 0 0 1</diffuse>
            <specular>1 0 0 1</specular>
          </material>
        </visual>
        <collision name='collision'>
          <geometry>
            <mesh>
              <uri>model://meshes/roda_direita_link.stl</uri>
            </mesh>
          </geometry>
        </collision>
      </link>
      <joint name='right_wheel_joint' type='revolute'>
        <pose relative_to='right_wheel' />
        <parent>chassis_link</parent>
        <child>right_wheel</child>
        <axis>
          <xyz expressed_in='__model__'>0 1 0</xyz>
          <limit>
            <lower>-1.79769e+308</lower>
            <upper>1.79769e+308</upper>
          </limit>
        </axis>
      </joint>
      <frame name="caster_frame" attached_to='chassis_link'>
        <pose>0.072581 0 -0.0025 -3.1408 0 0</pose>
      </frame>
      <link name='base_castor_link'>
        <pose relative_to='caster_frame' />
        <inertial>
          <mass>0.002</mass>
          <inertia>
            <ixx>0.0001</ixx>
            <ixy>0</ixy>
            <ixz>0</ixz>
            <iyy>0.0001</iyy>
            <iyz>0</iyz>
            <izz>0.0001</izz>
          </inertia>
        </inertial>
        <visual name='visual'>
          <geometry>
            <mesh>
              <uri>model://meshes/base_castor_link.stl</uri>
            </mesh>
          </geometry>
          <material>
            <ambient>0.0 1 0.0 1</ambient>
            <diffuse>0.0 1 0.0 1</diffuse>
            <specular>0.0 1 0.0 1</specular>
          </material>
        </visual>
        <collision name='collision'>
          <geometry>
            <mesh>
              <uri>model://meshes/base_castor_link.stl</uri>
            </mesh>
          </geometry>
        </collision>
      </link>
      <joint name='base_castor_joint' type='revolute'>
        <pose relative_to='base_castor_link' />
        <parent>chassis_link</parent>
        <child>base_castor_link</child>
        <axis>
          <xyz expressed_in='__model__'>0 0 1</xyz>
          <limit>
            <lower>-1.79769e+308</lower>
            <upper>1.79769e+308</upper>
          </limit>
        </axis>
      </joint>
      <link name='castor_wheel_link'>
        <pose relative_to="base_castor_link">0.015014 -0.00012272 0.02296 0 -1.57 1.5708</pose>
        <inertial>
          <mass>1</mass>
          <inertia>
            <ixx>6.3926680927577E-07</ixx>
            <ixy>-7.31657239076889E-23</ixy>
            <ixz>4.99800544060975E-23</ixz>
            <iyy>6.39299912774584E-07</iyy>
            <iyz>3.50834634007177E-09</iyz>
            <izz>1.01108533248037E-06</izz>
          </inertia>
        </inertial>
        <visual name='visual'>
          <geometry>
            <mesh>
              <uri>model://meshes/roda_castor_link.stl</uri>
            </mesh>
          </geometry>
          <material>
            <ambient>1 0 0 1</ambient>
            <diffuse>1 0 0 1</diffuse>
            <specular>1 0 0 1</specular>
          </material>
        </visual>
        <collision name='collision'>
          <geometry>
            <mesh>
              <uri>model://meshes/roda_castor_link.stl</uri>
            </mesh>
          </geometry>
        </collision>
      </link>
      <joint name='castor_wheel_joint' type='revolute'>
        <pose relative_to='castor_wheel_link' />
        <parent>base_castor_link</parent>
        <child>castor_wheel_link</child>
        <axis>
          <xyz expressed_in='__model__'>0 1 0</xyz>
          <limit>
            <lower>-1.79769e+308</lower>
            <upper>1.79769e+308</upper>
          </limit>
        </axis>
      </joint>

      <plugin
        filename="libignition-gazebo-diff-drive-system.so"
        name="ignition::gazebo::systems::DiffDrive">
        <left_joint>left_wheel_joint</left_joint>
        <right_joint>right_wheel_joint</right_joint>
        <wheel_separation>1.2</wheel_separation>
        <wheel_radius>0.4</wheel_radius>
        <odom_publish_frequency>1</odom_publish_frequency>
        <topic>cmd_vel</topic>
      </plugin>
    </model>

    <!-- Moving Forward-->
    <plugin filename="libignition-gazebo-triggered-publisher-system.so"
      name="ignition::gazebo::systems::TriggeredPublisher">
      <input type="ignition.msgs.Int32" topic="/keyboard/keypress">
        <match field="data">16777235</match>
      </input>
      <output type="ignition.msgs.Twist" topic="/cmd_vel">
        linear: {x: -0.5}, angular: {z: 0.0}
      </output>
    </plugin>

    <!-- Moving Backward-->
    <plugin filename="libignition-gazebo-triggered-publisher-system.so"
      name="ignition::gazebo::systems::TriggeredPublisher">
      <input type="ignition.msgs.Int32" topic="/keyboard/keypress">
        <match field="data">16777237</match>
      </input>
      <output type="ignition.msgs.Twist" topic="/cmd_vel">
        linear: {x: 0.5}, angular: {z: 0.0}
      </output>
    </plugin>

    <!-- Rotating Left-->
    <plugin filename="libignition-gazebo-triggered-publisher-system.so"
      name="ignition::gazebo::systems::TriggeredPublisher">
      <input type="ignition.msgs.Int32" topic="/keyboard/keypress">
        <match field="data">16777234</match>
      </input>
      <output type="ignition.msgs.Twist" topic="/cmd_vel">
        linear: {x: 0.0}, angular: {z: 0.5}
      </output>
    </plugin>

    <!-- Rotating Right-->
    <plugin filename="libignition-gazebo-triggered-publisher-system.so"
      name="ignition::gazebo::systems::TriggeredPublisher">
      <input type="ignition.msgs.Int32" topic="/keyboard/keypress">
        <match field="data">16777236</match>
      </input>
      <output type="ignition.msgs.Twist" topic="/cmd_vel">
        linear: {x: 0.0}, angular: {z: -0.5}
      </output>
    </plugin>

    <!-- Stop Number Zero -->
    <plugin filename="libignition-gazebo-triggered-publisher-system.so"
      name="ignition::gazebo::systems::TriggeredPublisher">
      <input type="ignition.msgs.Int32" topic="/keyboard/keypress">
        <match field="data">48</match>
      </input>
      <output type="ignition.msgs.Twist" topic="/cmd_vel">
        linear: {x: 0.0}, angular: {z: 0.0}
      </output>
    </plugin>
  </world>
</sdf>