<?xml version="1.0"?>
<sdf version="1.6">
  <property>
    <name>pi</name>
    <value>3.14159265359</value>
  </property>
  <world name="my_world">
    <physics name="1ms" type="ignored">
      <max_step_size>0.001</max_step_size>
      <real_time_factor>1.0</real_time_factor>
    </physics>
    <plugin
      filename="gz-sim-physics-system"
      name="gz::sim::systems::Physics">
    </plugin>
    <!-- 
  The Physics plugin is very important for simulating the dynamics of the world.
-->

    <plugin
      filename="gz-sim-user-commands-system"
      name="gz::sim::systems::UserCommands">
    </plugin>
    <!-- 
  The UserCommands plugin is responsible for creating models, moving models, deleting them and many
    other user commands.
-->
    <plugin
      filename="gz-sim-scene-broadcaster-system"
      name="gz::sim::systems::SceneBroadcaster">
    </plugin>
    <!-- Terreno plano -->
    <physics type="ode">
      <max_step_size>0.001</max_step_size>
      <real_time_update_rate>1000</real_time_update_rate>
      <real_time_factor>1.0</real_time_factor>
    </physics>

    <light type="directional" name="sun">
      <cast_shadows>true</cast_shadows>
      <pose>0 0 10 0 0 0</pose>
      <diffuse>0.8 0.8 0.8 1</diffuse>
      <specular>0.2 0.2 0.2 1</specular>
      <attenuation>
        <range>1000</range>
        <constant>0.9</constant>
        <linear>0.01</linear>
        <quadratic>0.001</quadratic>
      </attenuation>
      <direction>-0.5 0.1 -0.9</direction>
    </light>

    <!-- Inserir terreno -->
    <model name="ground_plane">
      <static>true</static>
      <link name="link">
        <collision name="collision">
          <geometry>
            <plane>
              <normal>0 0 1</normal>
              <size>50 50</size>
            </plane>
          </geometry>
        </collision>
        <visual name="visual">
          <geometry>
            <plane>
              <normal>0 0 1</normal>
              <size>50 50</size>
            </plane>
          </geometry>
          <material>
            <ambient>0.8 0.8 0.8 1</ambient>
            <diffuse>0.8 0.8 0.8 1</diffuse>
          </material>
        </visual>
      </link>
    </model>

    <!-- Adicionar iluminação 
    <scene>
      <ambient>0.4 0.4 0.4 1</ambient>
      <sky>
        <clouds>
          <speed>15</speed>
        </clouds>
      </sky>
      <shadows>true</shadows>
    </scene>
-->
    <model name='vehicle_blue' canonical_link='chassis_link'>
      <!-- 
              A tag <pose> e usada para definir a posicao e a orientacao do nosso modelo, e o atributo
              relative_to e usado para definir a pose do modelo em relacao a qualquer outro quadro. Se
              relative_to nao for definido, a <pose> do modelo sera relativa ao mundo.
          -->
      <pose relative_to='world'>0 -0.5 0 0 0 0</pose>
      <!-- 
              Os valores dentro da tag <pose> sao os seguintes: <pose>X Y Z R P Y</pose>,
              onde X, Y, Z representam a posicao do quadro e
              R, P, Y representam a orientacao em 
                  Roll (Rotacao em Rolo): O movimento de rotacao ao longo do eixo X. Imagine um aviao fazendo um
                  movimento de rolagem no ar, onde uma asa se eleva enquanto a outra abaixa. O angulo de
                  roll e medido em relacao ao eixo X, e geralmente e expresso em graus ou radianos.

                  Pitch (Arfagem): O movimento de rotacao ao longo do eixo Y. Isso e semelhante ao movimento de
                  inclinacao de um objeto para cima ou para baixo. O angulo de pitch e medido em relacao
                  ao eixo Y e tambem e expresso em graus ou radianos.

                  Yaw (Guinada): O movimento de rotacao ao longo do eixo Z. e como girar um objeto ao redor do eixo
                  vertical. O angulo de yaw e medido em relacao ao eixo Z e, assim como os outros, e
                  expresso em graus ou radianos.
          -->

      <link name='chassis_link'>
        <pose relative_to='__model__'>0 0 0.05 0 0 3.14159265359</pose>
        <inertial>
          <mass>0.012859</mass>
          <inertia>
            <ixx>5.2146E-06</ixx>
            <ixy>0</ixy>
            <ixz>0</ixz>
            <iyy>1.7957E-05</iyy>
            <iyz>0</iyz>
            <izz>2.2799E-05</izz>
          </inertia>
        </inertial>
        <visual name='visual'>
          <geometry>
            <mesh>
              <uri>model://meshes/chassis_link.stl</uri>
              <scale>1 1 1</scale>
            </mesh>
          </geometry>
          <material>
            <ambient>0.0 0.0 1.0 1</ambient>
            <diffuse>0.0 0.0 1.0 1</diffuse>
            <specular>0.0 0.0 1.0 1</specular>
          </material>
        </visual>
        <collision name='collision'>
          <geometry>
            <mesh>
              <uri>model://meshes/chassis_link.stl</uri>
              <scale>1 1 1</scale>
            </mesh>
          </geometry>
        </collision>
      </link>

      <!-- Câmera -->
      <link name="camera_link">
        <pose relative_to="chassis_link">-0.098 0 0.005 0 0 0</pose>
        <inertial>
          <mass>0.0001</mass>
          <inertia>
            <ixx>1.6667E-07</ixx>
            <iyy>1.6667E-07</iyy>
            <izz>1.6667E-07</izz>
          </inertia>
        </inertial>
        <collision name="collision">
          <geometry>
            <box>
              <size>0.005 0.01 0.01</size>
            </box>
          </geometry>
        </collision>
        <visual name="visual">
          <geometry>
            <box>
              <size>0.005 0.01 0.01</size>
            </box>
          </geometry>
        </visual>
        <camera name="camera">
          <pose>0 0 1 0 0 0</pose> <!-- Posição e orientação da câmera -->
          <horizontal_fov>1.047</horizontal_fov>
          <!-- Campo de visão horizontal em radianos (60 graus) -->
          <image>
            <width>640</width> <!-- Largura da imagem -->
            <height>480</height> <!-- Altura da imagem -->
            <format>R8G8B8</format> <!-- Formato da imagem (RGB) -->
          </image>
          <clip>
            <near>0.1</near> <!-- Distância de corte próxima -->
            <far>100</far> <!-- Distância de corte distante -->
          </clip>
        </camera>
      </link>
      <joint name='camera_joint' type='fixed'>
        <pose relative_to='camera_link' />
        <parent>chassis_link</parent>
        <child>camera_link</child>
      </joint>


      <!-- LiDAR -->
      <link name="lidar_link">
        <pose relative_to="camera_link">0 0 0.0075 0 0 0</pose>
        <inertial>
          <mass>0.0001</mass>
          <inertia>
            <ixx>1.6667E-07</ixx>
            <iyy>1.6667E-07</iyy>
            <izz>1.6667E-07</izz>
          </inertia>
        </inertial>
        <visual name='visual'>
          <geometry>
            <cylinder>
              <radius>0.005</radius>
              <length>0.005</length>
            </cylinder>
          </geometry>
          <material>
            <ambient>0.0 1 0.0 1</ambient>
            <diffuse>0.0 1 0.0 1</diffuse>
            <specular>0.0 1 0.0 1</specular>
          </material>
        </visual>
        <!-- LiDAR -->
        <sensor name="lidar" type="ray">
          <pose>0 0 1 0 0 0</pose> <!-- Posição e orientação do sensor -->
          <visualize>true</visualize>
          <update_rate>10.0</update_rate> <!-- Taxa de atualização em Hz -->
          <ray>
            <scan>
              <horizontal>
                <samples>360</samples> <!-- Número de amostras para 360 graus -->
                <resolution>1</resolution> <!-- Resolução angular em graus -->
                <min_angle>-1.5708</min_angle> <!-- Ângulo mínimo (-90 graus) -->
                <max_angle>1.5708</max_angle> <!-- Ângulo máximo (90 graus) -->
              </horizontal>
            </scan>
            <range>
              <min>0.01</min> <!-- Distância mínima de detecção (em metros) -->
              <max>50.0</max> <!-- Distância máxima de detecção (em metros) -->
              <resolution>0.01</resolution> <!-- Resolução da distância (em metros) -->
            </range>
          </ray>
        </sensor>
      </link>
      <joint name='lidar_joint' type='fixed'>
        <pose relative_to='lidar_link' />
        <parent>camera_link</parent>
        <child>lidar_link</child>
      </joint>
      <!-- Roda Esquerda -->
      <link name='left_wheel'>
        <pose relative_to="chassis_link">-0.033259 0.08025 -0.01375 -1.570796327 0.042481 0</pose>
        <inertial>
          <mass>0.0021404</mass>
          <inertia>
            <ixx>8.6283E-07</ixx>
            <ixy>0</ixy>
            <ixz>0</ixz>
            <iyy>8.6269E-07</iyy>
            <iyz>0</iyz>
            <izz>1.4515E-06</izz>
          </inertia>
        </inertial>

        <visual name='visual'>
          <geometry>
            <mesh>
              <uri>model://meshes/roda_esquerda_link.stl</uri>
              <scale>1 1 1</scale>
            </mesh>
          </geometry>
          <material>
            <ambient>1 0 0 1</ambient>
            <diffuse>1 0 0 1</diffuse>
            <specular>1 0 0 1</specular>
          </material>
        </visual>
        <collision name='collision'>
          <geometry>
            <mesh>
              <uri>model://meshes/roda_esquerda_link.stl</uri>
              <scale>1 1 1</scale>
            </mesh>
          </geometry>
        </collision>
      </link>
      <!-- Junta da Roda Esquerda -->
      <joint name='left_wheel_joint' type='revolute'>
        <pose relative_to='left_wheel' />
        <!-- 
                  Nossa primeira junta e a `left_wheel_joint`. Ela possui dois atributos: `name='left_wheel_joint'` e
                  `type='revolute'`. O tipo `revolute` fornece 1 grau de liberdade rotacional com limites
                  de junta. A pose da junta e a mesma que o quadro do elo filho, que e o quadro
                  `left_wheel`.
              -->
        <parent>chassis_link</parent>
        <child>left_wheel</child>
        <!-- 
                  Cada junta conecta dois elos (corpos) juntos. Aqui, estamos conectando o "chassis_link" com a
                  "left_wheel". "chassis_link" e o elo pai e "left_wheel" e o elo filho.
              -->
        <axis>
          <xyz expressed_in='__model__'>0 1 0</xyz>
          <!--
                      As juntas podem ser definidas como qualquer quadro ou ate mesmo quadros
                      arbitrarios.
                  -->
          <limit>
            <lower>-1.79769e+308</lower>    <!--negative
                      infinity-->
            <upper>1.79769e+308</upper>     <!--positive
                      infinity-->
          </limit>
        </axis>
        <!-- 
                  Aqui nos definimos o eixo de rotacao. O eixo de rotacao pode ser qualquer quadro, nao apenas o
                  quadro pai ou filho. Escolhemos o eixo y em relacao ao quadro do modelo, entao
                  colocamos 1 no elemento y e zeros nos outros. Para a junta revoluta, precisamos
                  definir os limites do angulo de rotacao nos tags `<lower>` e `<upper>`.

                  Observacao: Os angulos estao em radianos.
              -->
      </joint>
      <link name='right_wheel'>
        <pose relative_to="chassis_link">-0.033259 -0.08025 -0.01375 1.570796327 0.042481
          -3.14159265359</pose>
        <inertial>
          <mass>0.0021404</mass>
          <inertia>
            <ixx>8.6283E-07</ixx>
            <ixy>0</ixy>
            <ixz>0</ixz>
            <iyy>8.6269E-07</iyy>
            <iyz>0</iyz>
            <izz>1.4515E-06</izz>
          </inertia>
        </inertial>
        <visual name='visual'>
          <geometry>
            <mesh>
              <uri>model://meshes/roda_direita_link.stl</uri>
              <scale>1 1 1</scale>
            </mesh>
          </geometry>
          <material>
            <ambient>1 0 0 1</ambient>
            <diffuse>1 0 0 1</diffuse>
            <specular>1 0 0 1</specular>
          </material>
        </visual>
        <collision name='collision'>
          <geometry>
            <mesh>
              <uri>model://meshes/roda_direita_link.stl</uri>
              <scale>1 1 1</scale>
            </mesh>
          </geometry>
        </collision>
      </link>
      <joint name='right_wheel_joint' type='revolute'>
        <pose relative_to='right_wheel' />
        <parent>chassis_link</parent>
        <child>right_wheel</child>
        <axis>
          <xyz expressed_in='__model__'>0 1 0</xyz>
          <limit>
            <lower>-1.79769e+308</lower>    <!--negative
                      infinity-->
            <upper>1.79769e+308</upper>     <!--positive
                      infinity-->
          </limit>
        </axis>
      </joint>
      <frame name="caster_frame" attached_to='chassis_link'>
        <pose>0.072581 0 -0.0025 3.14159 0 0</pose>
      </frame>
      <!-- Roda Castor -->
      <link name='base_castor_link'>
        <pose relative_to='caster_frame'>0 0 0 0 0 0</pose>
        <inertial>
          <mass>0.0001</mass>
          <inertia>
            <ixx>1.6667E-07</ixx>
            <iyy>1.6667E-07</iyy>
            <izz>1.6667E-07</izz>
          </inertia>
        </inertial>
        <visual name='visual'>
          <geometry>
            <mesh>
              <uri>model://meshes/base_castor_link.stl</uri>
              <scale>1 1 1</scale>
            </mesh>
          </geometry>
          <material>
            <ambient>0.0 1 0.0 1</ambient>
            <diffuse>0.0 1 0.0 1</diffuse>
            <specular>0.0 1 0.0 1</specular>
          </material>
        </visual>
        <collision name='collision'>
          <geometry>
            <mesh>
              <uri>model://meshes/base_castor_link.stl</uri>
              <scale>1 1 1</scale>
            </mesh>
          </geometry>
        </collision>
      </link>
      <joint name='base_castor_joint' type='revolute'>
        <pose relative_to='base_castor_link' />
        <parent>chassis_link</parent>
        <child>base_castor_link</child>
        <axis>
          <xyz expressed_in='__model__'>0 0 1</xyz>
          <limit>
            <lower>-1.79769e+308</lower>    <!--negative
                      infinity-->
            <upper>1.79769e+308</upper>     <!--positive
                      infinity-->
          </limit>
        </axis>
      </joint>
      <link name='castor_wheel_link'>
        <pose relative_to="base_castor_link">0.0152 0 0.0231 1.570796327 0 0</pose>
        <inertial>
          <mass>0.00828739992319076</mass>
          <inertia>
            <ixx>6.3926680927577E-07</ixx>
            <ixy>-7.31657239076889E-23</ixy>
            <ixz>4.99800544060975E-23</ixz>
            <iyy>6.39299912774584E-07</iyy>
            <iyz>3.50834634007177E-09</iyz>
            <izz>1.01108533248037E-06</izz>
          </inertia>
        </inertial>
        <visual name='visual'>
          <geometry>
            <mesh>
              <uri>model://meshes/roda_castor_link.stl</uri>
              <scale>1 1 1</scale>
            </mesh>
          </geometry>
          <material>
            <ambient>1 0 0 1</ambient>
            <diffuse>1 0 0 1</diffuse>
            <specular>1 0 0 1</specular>
          </material>
        </visual>
        <collision name='collision'>
          <geometry>
            <mesh>
              <uri>model://meshes/roda_castor_link.stl</uri>
              <scale>1 1 1</scale>
            </mesh>
          </geometry>
        </collision>
      </link>
      <joint name='castor_wheel_joint' type='revolute'>
        <pose relative_to='castor_wheel_link' />
        <parent>base_castor_link</parent>
        <child>castor_wheel_link</child>
        <axis>
          <xyz expressed_in='__model__'>0 1 0</xyz>
          <limit>
            <lower>-1.79769e+308</lower>
            <upper>1.79769e+308</upper>
          </limit>
        </axis>
      </joint>
      <plugin filename="gz-sim-diff-drive-system"
        name="gz::sim::systems::DiffDrive">
        <left_joint>left_wheel_joint</left_joint>
        <right_joint>right_wheel_joint</right_joint>
        <wheel_separation>0.16050</wheel_separation>
        <wheel_radius>0.034</wheel_radius>
        <odom_publish_frequency>100</odom_publish_frequency>
        <topic>cmd_vel</topic>
      </plugin>
    </model>


    <include>
      <uri>model://room_wall_2x5m</uri>
      <pose>2.5 -1 0 0 0 0</pose>
      <name>a1</name>
    </include>

    <include>
      <uri>model://room_wall_2x5m_</uri>
      <pose relative_to="a1">2.5 2.5 0 0 0 0</pose>
      <name>a2</name>
    </include>

    <include>
      <uri>model://room_wall_2x5m_</uri>
      <pose relative_to="a1">-2.5 -2.5 0 0 0 0</pose>
      <name>a3</name>
    </include>

    <include>
      <uri>model://room_wall_2x5m_</uri>
      <pose relative_to="a2">0 -4 0 0 0 0</pose>
      <name>a4</name>
    </include>

    <include>
      <uri>model://room_wall_2x5m</uri>
      <pose relative_to="a1">0 -5 0 0 0 0</pose>
      <name>a5</name>
    </include>

    <include>
      <uri>model://room_wall_2x5m</uri>
      <pose relative_to="a5">2.5 0 0 0 0 0</pose>
      <name>a6</name>
    </include>

    <include>
      <uri>model://room_wall_2x5m</uri>
      <pose relative_to="a6">0 -2 0 0 0 0</pose>
      <name>a7</name>
    </include>

    <include>
      <uri>model://room_wall_2x5m</uri>
      <pose relative_to="a7">-5 0 0 0 0 0</pose>
      <name>a8</name>
    </include>

    <include>
      <uri>model://room_wall_2x5m_</uri>
      <pose relative_to="a3">0 -2 0 0 0 0</pose>
      <name>a9</name>
    </include>

    <include>
      <uri>model://room_wall_2x5m</uri>
      <pose relative_to="a1">0 6 0 0 0 0</pose>
      <name>b1</name>
    </include>

    <include>
      <uri>model://room_wall_2x5m_</uri>
      <pose relative_to="b1">2.5 2.5 0 0 0 0</pose>
      <name>b2</name>
    </include>

    <include>
      <uri>model://room_wall_2x5m_</uri>
      <pose relative_to="b1">-2.5 -2.5 0 0 0 0</pose>
      <name>b3</name>
    </include>

    <include>
      <uri>model://room_wall_2x5m_</uri>
      <pose relative_to="b2">2.5 -2 0 0 0 0</pose>
      <name>b4</name>
    </include>

    <include>
      <uri>model://room_wall_2x5m_</uri>
      <pose relative_to="b4">0 -5 0 0 0 0</pose>
      <name>b5</name>
    </include>

    <include>
      <uri>model://room_wall_2x5m_</uri>
      <pose relative_to="b5">0 -5 0 0 0 0</pose>
      <name>b6</name>
    </include>

    <include>
      <name>c0</name>
      <pose relative_to="b1">5 5 0 0 0 0</pose>
      <uri>model://room_wall_2x5m</uri>
    </include>

    <include>
      <name>c1</name>
      <pose relative_to="c0">-5 0 0 0 0 0</pose>
      <uri>model://room_wall_2x5m</uri>
    </include>

    <include>
      <name>c2</name>
      <pose relative_to="c1">-5 0 0 0 0 0</pose>
      <uri>model://room_wall_2x5m</uri>
    </include>

    <include>
      <name>c3</name>
      <pose relative_to="c2">-5 0 0 0 0 0</pose>
      <uri>model://room_wall_2x5m</uri>
    </include>

    <include>
      <name>c4</name>
      <pose relative_to="c3">-2.5 -2.5 0 0 0 0</pose>
      <uri>model://room_wall_2x5m_</uri>
    </include>

    <include>
      <name>c5</name>
      <pose relative_to="c4">0 -5 0 0 0 0</pose>
      <uri>model://room_wall_2x5m_</uri>
    </include>

    <include>
      <name>c6</name>
      <pose relative_to="c5">0 -5 0 0 0 0</pose>
      <uri>model://room_wall_2x5m_</uri>
    </include>

    <include>
      <name>c7</name>
      <pose relative_to="c6">0 -5 0 0 0 0</pose>
      <uri>model://room_wall_2x5m_</uri>
    </include>

    <include>
      <name>c8</name>
      <pose relative_to="c7">2.5 -2.5 0 0 0 0</pose>
      <uri>model://room_wall_2x5m</uri>
    </include>

    <include>
      <name>c9</name>
      <pose relative_to="c8">5 0 0 0 0 0</pose>
      <uri>model://room_wall_2x5m</uri>
    </include>

    <include>
      <name>c10</name>
      <pose relative_to="c9">5 0 0 0 0 0</pose>
      <uri>model://room_wall_2x5m</uri>
    </include>

    <include>
      <name>c11</name>
      <pose relative_to="c10">5 0 0 0 0 0</pose>
      <uri>model://room_wall_2x5m</uri>
    </include>

    <include>
      <name>c12</name>
      <pose relative_to="c11">2.5 2.5 0 0 0 0</pose>
      <uri>model://room_wall_2x5m_</uri>
    </include>

    <include>
      <name>c13</name>
      <pose relative_to="c12">0 5 0 0 0 0</pose>
      <uri>model://room_wall_2x5m_</uri>
    </include>

    <include>
      <name>c14</name>
      <pose relative_to="c13">0 5 0 0 0 0</pose>
      <uri>model://room_wall_2x5m_</uri>
    </include>

    <include>
      <name>c15</name>
      <pose relative_to="c14">0 5 0 0 0 0</pose>
      <uri>model://room_wall_2x5m_</uri>
    </include>

    <include>
      <name>d1</name>
      <pose relative_to="b1">-5 0 0 0 0 0</pose>
      <uri>model://room_wall_2x5m</uri>
    </include>

    <include>
      <name>d2</name>
      <pose relative_to="c8">0 2 0 0 0 0</pose>
      <uri>model://room_wall_2x5m</uri>
    </include>

    <include>
      <name>d3</name>
      <pose relative_to="d2">0 3.5 0 0 0 0</pose>
      <uri>model://room_wall_2x5m</uri>
    </include>

    <include>
      <name>d4</name>
      <pose relative_to="d3">0 3.5 0 0 0 0</pose>
      <uri>model://room_wall_2x5m</uri>
    </include>

    <include>
      <name>d5</name>
      <pose relative_to="d3">2.5 0 0 0 0 0</pose>
      <uri>model://room_wall_2x5m_</uri>
    </include>

    <include>
      <name>d6</name>
      <pose relative_to="a8">-0.5 0 0 0 0 0</pose>
      <uri>model://room_wall_2x5m</uri>
    </include>

    <include>
      <name>d7</name>
      <pose relative_to="a9">-3 0 0 0 0 0</pose>
      <uri>model://room_wall_2x5m_</uri>
    </include>

    <include>
      <name>d8</name>
      <pose relative_to="a3">-3 0 0 0 0 0</pose>
      <uri>model://room_wall_2x5m_</uri>
    </include>

    <include>
      <name>d9</name>
      <pose relative_to="a1">-2 0 0 0 0 0</pose>
      <uri>model://room_wall_2x5m</uri>
      <size>0.1 3.0 2</size>
    </include>
  </world>
</sdf>